<sdf version='1.6'>
  <world name='default'>
    <light name='sun' type='directional'>
      <cast_shadows>1</cast_shadows>
      <pose frame=''>0 0 10 0 -0 0</pose>
      <diffuse>0.8 0.8 0.8 1</diffuse>
      <specular>0.2 0.2 0.2 1</specular>
      <attenuation>
        <range>1000</range>
        <constant>0.9</constant>
        <linear>0.01</linear>
        <quadratic>0.001</quadratic>
      </attenuation>
      <direction>-0.5 0.1 -0.9</direction>
    </light>
    <model name='ground_plane'>
      <static>1</static>
      <link name='link'>
        <collision name='collision'>
          <geometry>
            <plane>
              <normal>0 0 1</normal>
              <size>100 100</size>
            </plane>
          </geometry>
          <surface>
            <friction>
              <ode>
                <mu>100</mu>
                <mu2>50</mu2>
              </ode>
              <torsional>
                <ode/>
              </torsional>
            </friction>
            <contact>
              <ode/>
            </contact>
            <bounce/>
          </surface>
          <max_contacts>10</max_contacts>
        </collision>
        <visual name='visual'>
          <cast_shadows>0</cast_shadows>
          <geometry>
            <plane>
              <normal>0 0 1</normal>
              <size>100 100</size>
            </plane>
          </geometry>
          <material>
            <script>
              <uri>file://media/materials/scripts/gazebo.material</uri>
              <name>Gazebo/Grey</name>
            </script>
          </material>
        </visual>
        <self_collide>0</self_collide>
        <enable_wind>0</enable_wind>
        <kinematic>0</kinematic>
      </link>
    </model>
    <model name='TEO_fixed'>
      <link name='TEO::RootWaist_links'>
        <pose frame=''>0 0 0.845 0 -0 0</pose>
        <inertial>
          <pose frame=''>-0.010985 -0.000323 0.033148 0 -0 0</pose>
          <mass>2.5</mass>
          <inertia>
            <ixx>0.0385308</ixx>
            <ixy>-1.35e-07</ixy>
            <ixz>0.000238121</ixz>
            <iyy>0.0173543</iyy>
            <iyz>-4.8e-10</iyz>
            <izz>0.0532316</izz>
          </inertia>
        </inertial>
        <visual name='RootWaist_links_visual'>
          <geometry>
            <mesh>
              <uri>model://teo/meshes/visual/RootWaist_links.dae</uri>
            </mesh>
          </geometry>
          <material>
            <ambient>0 0 0 1</ambient>
            <diffuse>0 0 0 1</diffuse>
            <specular>0 0 0 1</specular>
            <emissive>0 0 0 1</emissive>
          </material>
        </visual>
        <collision name='RootWaist_links_collision'>
          <geometry>
            <mesh>
              <uri>model://teo/meshes/collision/RootWaist_links.stl</uri>
            </mesh>
          </geometry>
          <max_contacts>10</max_contacts>
          <surface>
            <contact>
              <ode/>
            </contact>
            <bounce/>
            <friction>
              <torsional>
                <ode/>
              </torsional>
              <ode/>
            </friction>
          </surface>
        </collision>
        <self_collide>0</self_collide>
        <enable_wind>0</enable_wind>
        <kinematic>0</kinematic>
      </link>
      <link name='TEO::TEO_trunk::AxialWaist_link'>
        <pose frame=''>0 0 1.0382 0 -0 0</pose>
        <inertial>
          <pose frame=''>-0.002235 -0.000979 -0.018814 0 -0 0</pose>
          <mass>1</mass>
          <inertia>
            <ixx>0.00197759</ixx>
            <ixy>2.06e-06</ixy>
            <ixz>2.97e-05</ixz>
            <iyy>0.000899729</iyy>
            <iyz>-3.07e-06</iyz>
            <izz>0.00147175</izz>
          </inertia>
        </inertial>
        <visual name='AxialWaist_visual'>
          <geometry>
            <mesh>
              <uri>model://teo/meshes/visual/AxialWaist.dae</uri>
            </mesh>
          </geometry>
          <material>
            <ambient>0.792157 0.819608 0.933333 1</ambient>
            <diffuse>0.792157 0.819608 0.933333 1</diffuse>
            <specular>0.633726 0.655686 0.746667 1</specular>
            <emissive>0 0 0 1</emissive>
          </material>
        </visual>
        <collision name='AxialWaist_collision'>
          <geometry>
            <mesh>
              <uri>model://teo/meshes/collision/AxialWaist.stl</uri>
            </mesh>
          </geometry>
          <max_contacts>10</max_contacts>
          <surface>
            <contact>
              <ode/>
            </contact>
            <bounce/>
            <friction>
              <torsional>
                <ode/>
              </torsional>
              <ode/>
            </friction>
          </surface>
        </collision>
        <self_collide>0</self_collide>
        <enable_wind>0</enable_wind>
        <kinematic>0</kinematic>
      </link>
      <joint name='TEO::TEO_trunk::AxialWaist' type='revolute'>
        <parent>TEO::RootWaist_links</parent>
        <child>TEO::TEO_trunk::AxialWaist_link</child>
        <axis>
          <xyz>0 0 1</xyz>
          <limit>
            <lower>-1.03</lower>
            <upper>0.81</upper>
          </limit>
          <dynamics>
            <damping>0.001</damping>
            <friction>0.7</friction>
            <spring_reference>0</spring_reference>
            <spring_stiffness>0</spring_stiffness>
          </dynamics>
          <use_parent_model_frame>0</use_parent_model_frame>
        </axis>
      </joint>
      <link name='TEO::TEO_trunk::FrontalWaist_link'>
        <pose frame=''>0 0 1.0382 0 -0 0</pose>
        <inertial>
          <pose frame=''>0.032985 -0.007876 0.220667 0 -0 0</pose>
          <mass>14.2355</mass>
          <inertia>
            <ixx>0.335665</ixx>
            <ixy>0.000162127</ixy>
            <ixz>0.0118582</ixz>
            <iyy>0.126532</iyy>
            <iyz>0.000914091</iyz>
            <izz>0.263359</izz>
          </inertia>
        </inertial>
        <visual name='FrontalWaist_visual'>
          <geometry>
            <mesh>
              <uri>model://teo/meshes/visual/RootWaist.dae</uri>
            </mesh>
          </geometry>
          <material>
            <ambient>0.905882 0 0.172549 1</ambient>
            <diffuse>0.905882 0 0.172549 1</diffuse>
            <specular>0.452941 0 0.086275 1</specular>
            <emissive>0 0 0 1</emissive>
          </material>
        </visual>
        <collision name='FrontalWaist_collision'>
          <geometry>
            <mesh>
              <uri>model://teo/meshes/collision/RootWaist.stl</uri>
            </mesh>
          </geometry>
          <max_contacts>10</max_contacts>
          <surface>
            <contact>
              <ode/>
            </contact>
            <bounce/>
            <friction>
              <torsional>
                <ode/>
              </torsional>
              <ode/>
            </friction>
          </surface>
        </collision>
        <self_collide>0</self_collide>
        <enable_wind>0</enable_wind>
        <kinematic>0</kinematic>
      </link>
      <joint name='TEO::TEO_trunk::FrontalWaist' type='revolute'>
        <parent>TEO::TEO_trunk::AxialWaist_link</parent>
        <child>TEO::TEO_trunk::FrontalWaist_link</child>
        <axis>
          <xyz>0 1 0</xyz>
          <limit>
            <lower>-1.58</lower>
            <upper>0.18</upper>
          </limit>
          <dynamics>
            <damping>0.001</damping>
            <friction>0.7</friction>
            <spring_reference>0</spring_reference>
            <spring_stiffness>0</spring_stiffness>
          </dynamics>
          <use_parent_model_frame>0</use_parent_model_frame>
        </axis>
      </joint>
      <plugin name='controlboard_trunk' filename='libgazebo_yarp_controlboard.so'>
        <yarpConfigurationFile>model://teo/conf/gazebo_teo_trunk.ini</yarpConfigurationFile>
      </plugin>
      <link name='TEO::TEO_head::AxialNeck_link'>
        <pose frame=''>0 0 1.4732 0 -0 0</pose>
        <inertial>
          <pose frame=''>0.000302 0.000193 -0.0452 0 -0 0</pose>
          <mass>1</mass>
          <inertia>
            <ixx>0.000939063</ixx>
            <ixy>0</ixy>
            <ixz>0</ixz>
            <iyy>0.000939063</iyy>
            <iyz>0</iyz>
            <izz>0.000528125</izz>
          </inertia>
        </inertial>
        <visual name='AxialNeck_visual'>
          <geometry>
            <mesh>
              <uri>model://teo/meshes/visual/AxialNeck.dae</uri>
            </mesh>
          </geometry>
          <material>
            <ambient>0.792157 0.819608 0.933333 1</ambient>
            <diffuse>0.792157 0.819608 0.933333 1</diffuse>
            <specular>0.633726 0.655686 0.746667 1</specular>
            <emissive>0 0 0 1</emissive>
          </material>
        </visual>
        <collision name='AxialNeck_collision'>
          <geometry>
            <mesh>
              <uri>model://teo/meshes/collision/AxialNeck.stl</uri>
            </mesh>
          </geometry>
          <max_contacts>10</max_contacts>
          <surface>
            <contact>
              <ode/>
            </contact>
            <bounce/>
            <friction>
              <torsional>
                <ode/>
              </torsional>
              <ode/>
            </friction>
          </surface>
        </collision>
        <self_collide>0</self_collide>
        <enable_wind>0</enable_wind>
        <kinematic>0</kinematic>
      </link>
      <joint name='TEO::TEO_head::AxialNeck' type='revolute'>
        <parent>TEO::TEO_trunk::FrontalWaist_link</parent>
        <child>TEO::TEO_head::AxialNeck_link</child>
        <axis>
          <xyz>0 0 1</xyz>
          <limit>
            <lower>-1.22</lower>
            <upper>1.22</upper>
          </limit>
          <dynamics>
            <damping>0.001</damping>
            <friction>0.7</friction>
            <spring_reference>0</spring_reference>
            <spring_stiffness>0</spring_stiffness>
          </dynamics>
          <use_parent_model_frame>0</use_parent_model_frame>
        </axis>
      </joint>
      <link name='TEO::TEO_head::FrontalNeck_link'>
        <pose frame=''>0 0 1.5057 0 -0 0</pose>
        <inertial>
          <pose frame=''>-0.002729 -8.6e-05 0.067027 0 -0 0</pose>
          <mass>2</mass>
          <inertia>
            <ixx>0.00759932</ixx>
            <ixy>5.83e-09</ixy>
            <ixz>6.58e-05</ixz>
            <iyy>0.00832527</iyy>
            <iyz>-7.43e-09</iyz>
            <izz>0.0114035</izz>
          </inertia>
        </inertial>
        <visual name='FrontalNeck_visual'>
          <geometry>
            <mesh>
              <uri>model://teo/meshes/visual/FrontalNeck.dae</uri>
            </mesh>
          </geometry>
          <material>
            <ambient>1 1 1 1</ambient>
            <diffuse>0.7 0.7 0.7 1</diffuse>
            <specular>0.2 0.2 0.2 1</specular>
            <emissive>0 0 0 1</emissive>
          </material>
        </visual>
        <collision name='FrontalNeck_collision'>
          <geometry>
            <mesh>
              <uri>model://teo/meshes/collision/FrontalNeck.stl</uri>
            </mesh>
          </geometry>
          <max_contacts>10</max_contacts>
          <surface>
            <contact>
              <ode/>
            </contact>
            <bounce/>
            <friction>
              <torsional>
                <ode/>
              </torsional>
              <ode/>
            </friction>
          </surface>
        </collision>
        <sensor name='xtion_rgbd' type='depth'>
          <pose frame=''>0 0 0 0 -0 0</pose>
          <camera name='__default__'>
            <horizontal_fov>1.01</horizontal_fov>
            <image>
              <width>640</width>
              <height>480</height>
            </image>
            <clip>
              <near>0.8</near>
              <far>3.5</far>
            </clip>
            <lens>
              <type>stereographic</type>
              <scale_to_hfov>1</scale_to_hfov>
            </lens>
          </camera>
          <always_on>1</always_on>
          <update_rate>30</update_rate>
          <visualize>1</visualize>
          <plugin name='xtion_rgbd_plugin' filename='libgazebo_yarp_depthCamera.so'>
            <yarpConfigurationFile>model://teo/conf/gazebo_xtion_rgbd.ini</yarpConfigurationFile>
          </plugin>
        </sensor>
        <self_collide>0</self_collide>
        <enable_wind>0</enable_wind>
        <kinematic>0</kinematic>
      </link>
      <joint name='TEO::TEO_head::FrontalNeck' type='revolute'>
        <parent>TEO::TEO_head::AxialNeck_link</parent>
        <child>TEO::TEO_head::FrontalNeck_link</child>
        <axis>
          <xyz>0 1 0</xyz>
          <limit>
            <lower>-0.51</lower>
            <upper>0.15</upper>
          </limit>
          <dynamics>
            <damping>0.001</damping>
            <friction>0.7</friction>
            <spring_reference>0</spring_reference>
            <spring_stiffness>0</spring_stiffness>
          </dynamics>
          <use_parent_model_frame>0</use_parent_model_frame>
        </axis>
      </joint>
      <plugin name='controlboard_head' filename='libgazebo_yarp_controlboard.so'>
        <yarpConfigurationFile>model://teo/conf/gazebo_teo_head.ini</yarpConfigurationFile>
      </plugin>
      <link name='TEO::TEO_rightArm::FrontalRightShoulder_link'>
        <pose frame=''>0 -0.26292 1.3432 0 -0 0</pose>
        <inertial>
          <pose frame=''>-0.002267 -0.056164 0.008456 0 -0 0</pose>
          <mass>2</mass>
          <inertia>
            <ixx>0.00422679</ixx>
            <ixy>8.44e-05</ixy>
            <ixz>-1.17e-05</ixz>
            <iyy>0.00212728</iyy>
            <iyz>-0.000280493</iyz>
            <izz>0.00409316</izz>
          </inertia>
        </inertial>
        <visual name='FrontalRightShoulder_visual'>
          <geometry>
            <mesh>
              <uri>model://teo/meshes/visual/FrontalRightShoulder.dae</uri>
            </mesh>
          </geometry>
          <material>
            <ambient>0.792157 0.819608 0.933333 1</ambient>
            <diffuse>0.792157 0.819608 0.933333 1</diffuse>
            <specular>0.633726 0.655686 0.746667 1</specular>
            <emissive>0 0 0 1</emissive>
          </material>
        </visual>
        <collision name='FrontalRightShoulder_collision'>
          <geometry>
            <mesh>
              <uri>model://teo/meshes/collision/FrontalRightShoulder.stl</uri>
            </mesh>
          </geometry>
          <max_contacts>10</max_contacts>
          <surface>
            <contact>
              <ode/>
            </contact>
            <bounce/>
            <friction>
              <torsional>
                <ode/>
              </torsional>
              <ode/>
            </friction>
          </surface>
        </collision>
        <self_collide>0</self_collide>
        <enable_wind>0</enable_wind>
        <kinematic>0</kinematic>
      </link>
      <joint name='TEO::TEO_rightArm::FrontalRightShoulder' type='revolute'>
        <parent>TEO::TEO_trunk::FrontalWaist_link</parent>
        <child>TEO::TEO_rightArm::FrontalRightShoulder_link</child>
        <axis>
          <xyz>0 1 0</xyz>
          <limit>
            <lower>-1.71</lower>
            <upper>1.85</upper>
          </limit>
          <dynamics>
            <damping>0.001</damping>
            <friction>0.7</friction>
            <spring_reference>0</spring_reference>
            <spring_stiffness>0</spring_stiffness>
          </dynamics>
          <use_parent_model_frame>0</use_parent_model_frame>
        </axis>
      </joint>
      <link name='TEO::TEO_rightArm::SagittalRightShoulder_link'>
        <pose frame=''>0 -0.34692 1.3432 0 -0 0</pose>
        <inertial>
          <pose frame=''>-0.008472 -0.004826 -0.027321 0 -0 0</pose>
          <mass>1</mass>
          <inertia>
            <ixx>0.00161093</ixx>
            <ixy>-6.9e-05</ixy>
            <ixz>-0.000214886</ixz>
            <iyy>0.00218778</iyy>
            <iyz>-6.9e-05</iyz>
            <izz>0.00117353</izz>
          </inertia>
        </inertial>
        <visual name='SagittalRightShoulder_visual'>
          <geometry>
            <mesh>
              <uri>model://teo/meshes/visual/SagittalRightShoulder.dae</uri>
            </mesh>
          </geometry>
          <material>
            <ambient>0.792157 0.819608 0.933333 1</ambient>
            <diffuse>0.792157 0.819608 0.933333 1</diffuse>
            <specular>0.633726 0.655686 0.746667 1</specular>
            <emissive>0 0 0 1</emissive>
          </material>
        </visual>
        <collision name='SagittalRightShoulder_collision'>
          <geometry>
            <mesh>
              <uri>model://teo/meshes/collision/SagittalRightShoulder.stl</uri>
            </mesh>
          </geometry>
          <max_contacts>10</max_contacts>
          <surface>
            <contact>
              <ode/>
            </contact>
            <bounce/>
            <friction>
              <torsional>
                <ode/>
              </torsional>
              <ode/>
            </friction>
          </surface>
        </collision>
        <self_collide>0</self_collide>
        <enable_wind>0</enable_wind>
        <kinematic>0</kinematic>
      </link>
      <joint name='TEO::TEO_rightArm::SagittalRightShoulder' type='revolute'>
        <parent>TEO::TEO_rightArm::FrontalRightShoulder_link</parent>
        <child>TEO::TEO_rightArm::SagittalRightShoulder_link</child>
        <axis>
          <xyz>1 0 0</xyz>
          <limit>
            <lower>-1.32</lower>
            <upper>0.39</upper>
          </limit>
          <dynamics>
            <damping>0.001</damping>
            <friction>0.7</friction>
            <spring_reference>0</spring_reference>
            <spring_stiffness>0</spring_stiffness>
          </dynamics>
          <use_parent_model_frame>0</use_parent_model_frame>
        </axis>
      </joint>
      <link name='TEO::TEO_rightArm::AxialRightShoulder_link'>
        <pose frame=''>0 -0.34692 1.0142 0 -0 0</pose>
        <inertial>
          <pose frame=''>0.000347 0.000245 0.107382 0 -0 0</pose>
          <mass>1</mass>
          <inertia>
            <ixx>1</ixx>
            <ixy>0</ixy>
            <ixz>0</ixz>
            <iyy>1</iyy>
            <iyz>0</iyz>
            <izz>1</izz>
          </inertia>
        </inertial>
        <visual name='AxialRightShoulder_visual'>
          <geometry>
            <mesh>
              <uri>model://teo/meshes/visual/AxialRightShoulder.dae</uri>
            </mesh>
          </geometry>
          <material>
            <ambient>0.792157 0.819608 0.933333 1</ambient>
            <diffuse>0.792157 0.819608 0.933333 1</diffuse>
            <specular>0.633726 0.655686 0.746667 1</specular>
            <emissive>0 0 0 1</emissive>
          </material>
        </visual>
        <collision name='AxialRightShoulder_collision'>
          <geometry>
            <mesh>
              <uri>model://teo/meshes/collision/AxialRightShoulder.stl</uri>
            </mesh>
          </geometry>
          <max_contacts>10</max_contacts>
          <surface>
            <contact>
              <ode/>
            </contact>
            <bounce/>
            <friction>
              <torsional>
                <ode/>
              </torsional>
              <ode/>
            </friction>
          </surface>
        </collision>
        <self_collide>0</self_collide>
        <enable_wind>0</enable_wind>
        <kinematic>0</kinematic>
      </link>
      <joint name='TEO::TEO_rightArm::AxialRightShoulder' type='revolute'>
        <parent>TEO::TEO_rightArm::SagittalRightShoulder_link</parent>
        <child>TEO::TEO_rightArm::AxialRightShoulder_link</child>
        <axis>
          <xyz>0 0 1</xyz>
          <limit>
            <lower>-1.4</lower>
            <upper>0.99</upper>
          </limit>
          <dynamics>
            <damping>0.001</damping>
            <friction>0.7</friction>
            <spring_reference>0</spring_reference>
            <spring_stiffness>0</spring_stiffness>
          </dynamics>
          <use_parent_model_frame>0</use_parent_model_frame>
        </axis>
      </joint>
      <link name='TEO::TEO_rightArm::FrontalRightElbow_link'>
        <pose frame=''>0 -0.34692 1.0142 0 -0 0</pose>
        <inertial>
          <pose frame=''>0.000237 -4e-05 -0.04998 0 -0 0</pose>
          <mass>1</mass>
          <inertia>
            <ixx>0.00259003</ixx>
            <ixy>0</ixy>
            <ixz>0</ixz>
            <iyy>0.00262307</iyy>
            <iyz>0</iyz>
            <izz>0.000446024</izz>
          </inertia>
        </inertial>
        <visual name='FrontalRightElbow_visual'>
          <geometry>
            <mesh>
              <uri>model://teo/meshes/visual/FrontalRightElbow.dae</uri>
            </mesh>
          </geometry>
          <material>
            <ambient>0.792157 0.819608 0.933333 1</ambient>
            <diffuse>0.792157 0.819608 0.933333 1</diffuse>
            <specular>0.633726 0.655686 0.746667 1</specular>
            <emissive>0 0 0 1</emissive>
          </material>
        </visual>
        <collision name='FrontalRightElbow_collision'>
          <geometry>
            <mesh>
              <uri>model://teo/meshes/collision/FrontalRightElbow.stl</uri>
            </mesh>
          </geometry>
          <max_contacts>10</max_contacts>
          <surface>
            <contact>
              <ode/>
            </contact>
            <bounce/>
            <friction>
              <torsional>
                <ode/>
              </torsional>
              <ode/>
            </friction>
          </surface>
        </collision>
        <self_collide>0</self_collide>
        <enable_wind>0</enable_wind>
        <kinematic>0</kinematic>
      </link>
      <joint name='TEO::TEO_rightArm::FrontalRightElbow' type='revolute'>
        <parent>TEO::TEO_rightArm::AxialRightShoulder_link</parent>
        <child>TEO::TEO_rightArm::FrontalRightElbow_link</child>
        <axis>
          <xyz>0 1 0</xyz>
          <limit>
            <lower>-1.74</lower>
            <upper>1.72</upper>
          </limit>
          <dynamics>
            <damping>0.001</damping>
            <friction>0.7</friction>
            <spring_reference>0</spring_reference>
            <spring_stiffness>0</spring_stiffness>
          </dynamics>
          <use_parent_model_frame>0</use_parent_model_frame>
        </axis>
      </joint>
      <link name='TEO::TEO_rightArm::AxialRightWrist_link'>
        <pose frame=''>0 -0.34692 0.8122 0 -0 0</pose>
        <inertial>
          <pose frame=''>-0.001151 0.000603 0.02464 0 -0 0</pose>
          <mass>0.63149</mass>
          <inertia>
            <ixx>0.000701463</ixx>
            <ixy>-1.05e-05</ixy>
            <ixz>-1.09e-05</ixz>
            <iyy>0.000612806</iyy>
            <iyz>1.15e-05</iyz>
            <izz>0.000326949</izz>
          </inertia>
        </inertial>
        <visual name='AxialRightWrist_visual'>
          <geometry>
            <mesh>
              <uri>model://teo/meshes/visual/AxialRightWrist.dae</uri>
            </mesh>
          </geometry>
          <material>
            <ambient>0.792157 0.819608 0.933333 1</ambient>
            <diffuse>0.792157 0.819608 0.933333 1</diffuse>
            <specular>0.633726 0.655686 0.746667 1</specular>
            <emissive>0 0 0 1</emissive>
          </material>
        </visual>
        <collision name='AxialRightWrist_collision'>
          <geometry>
            <mesh>
              <uri>model://teo/meshes/collision/AxialRightWrist.stl</uri>
            </mesh>
          </geometry>
          <max_contacts>10</max_contacts>
          <surface>
            <contact>
              <ode/>
            </contact>
            <bounce/>
            <friction>
              <torsional>
                <ode/>
              </torsional>
              <ode/>
            </friction>
          </surface>
        </collision>
        <self_collide>0</self_collide>
        <enable_wind>0</enable_wind>
        <kinematic>0</kinematic>
      </link>
      <joint name='TEO::TEO_rightArm::AxialRightWrist' type='revolute'>
        <parent>TEO::TEO_rightArm::FrontalRightElbow_link</parent>
        <child>TEO::TEO_rightArm::AxialRightWrist_link</child>
        <axis>
          <xyz>0 0 1</xyz>
          <limit>
            <lower>-1.4</lower>
            <upper>1.74</upper>
          </limit>
          <dynamics>
            <damping>0.001</damping>
            <friction>0.7</friction>
            <spring_reference>0</spring_reference>
            <spring_stiffness>0</spring_stiffness>
          </dynamics>
          <use_parent_model_frame>0</use_parent_model_frame>
        </axis>
      </joint>
      <link name='TEO::TEO_rightArm::FrontalRightWrist_link'>
        <pose frame=''>0 -0.34692 0.8122 0 -0 0</pose>
        <inertial>
          <pose frame=''>-0.002314 7e-05 -0.108635 0 -0 0</pose>
          <mass>1.17</mass>
          <inertia>
            <ixx>0.00532996</ixx>
            <ixy>1.02e-07</ixy>
            <ixz>0.000114751</ixz>
            <iyy>0.00534528</iyy>
            <iyz>-8.07e-06</iyz>
            <izz>0.000883179</izz>
          </inertia>
        </inertial>
        <visual name='FrontalRightWrist_visual'>
          <geometry>
            <mesh>
              <uri>model://teo/meshes/visual/FrontalRightWrist.dae</uri>
            </mesh>
          </geometry>
          <material>
            <ambient>0.792157 0.819608 0.933333 1</ambient>
            <diffuse>0.792157 0.819608 0.933333 1</diffuse>
            <specular>0.633726 0.655686 0.746667 1</specular>
            <emissive>0 0 0 1</emissive>
          </material>
        </visual>
        <collision name='FrontalRightWrist_collision'>
          <geometry>
            <mesh>
              <uri>model://teo/meshes/collision/FrontalRightWrist.stl</uri>
            </mesh>
          </geometry>
          <max_contacts>10</max_contacts>
          <surface>
            <contact>
              <ode/>
            </contact>
            <bounce/>
            <friction>
              <torsional>
                <ode/>
              </torsional>
              <ode/>
            </friction>
          </surface>
        </collision>
        <self_collide>0</self_collide>
        <enable_wind>0</enable_wind>
        <kinematic>0</kinematic>
      </link>
      <joint name='TEO::TEO_rightArm::FrontalRightWrist' type='revolute'>
        <parent>TEO::TEO_rightArm::AxialRightWrist_link</parent>
        <child>TEO::TEO_rightArm::FrontalRightWrist_link</child>
        <axis>
          <xyz>0 1 0</xyz>
          <limit>
            <lower>-2.01</lower>
            <upper>0.78</upper>
          </limit>
          <dynamics>
            <damping>0.001</damping>
            <friction>0.7</friction>
            <spring_reference>0</spring_reference>
            <spring_stiffness>0</spring_stiffness>
          </dynamics>
          <use_parent_model_frame>0</use_parent_model_frame>
        </axis>
      </joint>
      <plugin name='controlboard_rightArm' filename='libgazebo_yarp_controlboard.so'>
        <yarpConfigurationFile>model://teo/conf/gazebo_teo_rightArm.ini</yarpConfigurationFile>
      </plugin>
      <link name='TEO::TEO_leftArm::FrontalLeftShoulder_link'>
        <pose frame=''>0 0.26292 1.3432 0 -0 0</pose>
        <inertial>
          <pose frame=''>-0.002272 0.056186 0.008165 0 -0 0</pose>
          <mass>2</mass>
          <inertia>
            <ixx>0.00422679</ixx>
            <ixy>-8.55e-05</ixy>
            <ixz>-1.17e-05</ixz>
            <iyy>0.00212734</iyy>
            <iyz>0.000280493</iyz>
            <izz>0.00409322</izz>
          </inertia>
        </inertial>
        <visual name='FrontalLeftShoulder_visual'>
          <geometry>
            <mesh>
              <uri>model://teo/meshes/visual/FrontalLeftShoulder.dae</uri>
            </mesh>
          </geometry>
          <material>
            <ambient>0.792157 0.819608 0.933333 1</ambient>
            <diffuse>0.792157 0.819608 0.933333 1</diffuse>
            <specular>0.633726 0.655686 0.746667 1</specular>
            <emissive>0 0 0 1</emissive>
          </material>
        </visual>
        <collision name='FrontalLeftShoulder_collision'>
          <geometry>
            <mesh>
              <uri>model://teo/meshes/collision/FrontalLeftShoulder.stl</uri>
            </mesh>
          </geometry>
          <max_contacts>10</max_contacts>
          <surface>
            <contact>
              <ode/>
            </contact>
            <bounce/>
            <friction>
              <torsional>
                <ode/>
              </torsional>
              <ode/>
            </friction>
          </surface>
        </collision>
        <self_collide>0</self_collide>
        <enable_wind>0</enable_wind>
        <kinematic>0</kinematic>
      </link>
      <joint name='TEO::TEO_leftArm::FrontalLeftShoulder' type='revolute'>
        <parent>TEO::TEO_trunk::FrontalWaist_link</parent>
        <child>TEO::TEO_leftArm::FrontalLeftShoulder_link</child>
        <axis>
          <xyz>0 1 0</xyz>
          <limit>
            <lower>-1.69</lower>
            <upper>1.98</upper>
          </limit>
          <dynamics>
            <damping>0.001</damping>
            <friction>0.7</friction>
            <spring_reference>0</spring_reference>
            <spring_stiffness>0</spring_stiffness>
          </dynamics>
          <use_parent_model_frame>0</use_parent_model_frame>
        </axis>
      </joint>
      <link name='TEO::TEO_leftArm::SagittalLeftShoulder_link'>
        <pose frame=''>0 0.34692 1.3432 0 -0 0</pose>
        <inertial>
          <pose frame=''>-0.008047 0.004937 -0.027619 0 -0 0</pose>
          <mass>1</mass>
          <inertia>
            <ixx>0.00161092</ixx>
            <ixy>6.9e-05</ixy>
            <ixz>-0.000214885</ixz>
            <iyy>0.00218777</iyy>
            <iyz>-0.000163004</iyz>
            <izz>0.00117353</izz>
          </inertia>
        </inertial>
        <visual name='SagittalLeftShoulder_visual'>
          <geometry>
            <mesh>
              <uri>model://teo/meshes/visual/SagittalLeftShoulder.dae</uri>
            </mesh>
          </geometry>
          <material>
            <ambient>0.792157 0.819608 0.933333 1</ambient>
            <diffuse>0.792157 0.819608 0.933333 1</diffuse>
            <specular>0.633726 0.655686 0.746667 1</specular>
            <emissive>0 0 0 1</emissive>
          </material>
        </visual>
        <collision name='SagittalLeftShoulder_collision'>
          <geometry>
            <mesh>
              <uri>model://teo/meshes/collision/SagittalLeftShoulder.stl</uri>
            </mesh>
          </geometry>
          <max_contacts>10</max_contacts>
          <surface>
            <contact>
              <ode/>
            </contact>
            <bounce/>
            <friction>
              <torsional>
                <ode/>
              </torsional>
              <ode/>
            </friction>
          </surface>
        </collision>
        <self_collide>0</self_collide>
        <enable_wind>0</enable_wind>
        <kinematic>0</kinematic>
      </link>
      <joint name='TEO::TEO_leftArm::SagittalLeftShoulder' type='revolute'>
        <parent>TEO::TEO_leftArm::FrontalLeftShoulder_link</parent>
        <child>TEO::TEO_leftArm::SagittalLeftShoulder_link</child>
        <axis>
          <xyz>1 0 0</xyz>
          <limit>
            <lower>-0.42</lower>
            <upper>1.34</upper>
          </limit>
          <dynamics>
            <damping>0.001</damping>
            <friction>0.7</friction>
            <spring_reference>0</spring_reference>
            <spring_stiffness>0</spring_stiffness>
          </dynamics>
          <use_parent_model_frame>0</use_parent_model_frame>
        </axis>
      </joint>
      <link name='TEO::TEO_leftArm::AxialLeftShoulder_link'>
        <pose frame=''>0 0.34692 1.0142 0 -0 0</pose>
        <inertial>
          <pose frame=''>-0.000172 0.000249 0.100649 0 -0 0</pose>
          <mass>1</mass>
          <inertia>
            <ixx>1</ixx>
            <ixy>0</ixy>
            <ixz>0</ixz>
            <iyy>1</iyy>
            <iyz>0</iyz>
            <izz>1</izz>
          </inertia>
        </inertial>
        <visual name='AxialLeftShoulder_visual'>
          <geometry>
            <mesh>
              <uri>model://teo/meshes/visual/AxialLeftShoulder.dae</uri>
            </mesh>
          </geometry>
          <material>
            <ambient>0.792157 0.819608 0.933333 1</ambient>
            <diffuse>0.792157 0.819608 0.933333 1</diffuse>
            <specular>0.633726 0.655686 0.746667 1</specular>
            <emissive>0 0 0 1</emissive>
          </material>
        </visual>
        <collision name='AxialLeftShoulder_collision'>
          <geometry>
            <mesh>
              <uri>model://teo/meshes/collision/AxialLeftShoulder.stl</uri>
            </mesh>
          </geometry>
          <max_contacts>10</max_contacts>
          <surface>
            <contact>
              <ode/>
            </contact>
            <bounce/>
            <friction>
              <torsional>
                <ode/>
              </torsional>
              <ode/>
            </friction>
          </surface>
        </collision>
        <self_collide>0</self_collide>
        <enable_wind>0</enable_wind>
        <kinematic>0</kinematic>
      </link>
      <joint name='TEO::TEO_leftArm::AxialLeftShoulder' type='revolute'>
        <parent>TEO::TEO_leftArm::SagittalLeftShoulder_link</parent>
        <child>TEO::TEO_leftArm::AxialLeftShoulder_link</child>
        <axis>
          <xyz>0 0 1</xyz>
          <limit>
            <lower>-0.9</lower>
            <upper>1.47</upper>
          </limit>
          <dynamics>
            <damping>0.001</damping>
            <friction>0.7</friction>
            <spring_reference>0</spring_reference>
            <spring_stiffness>0</spring_stiffness>
          </dynamics>
          <use_parent_model_frame>0</use_parent_model_frame>
        </axis>
      </joint>
      <link name='TEO::TEO_leftArm::FrontalLeftElbow_link'>
        <pose frame=''>0 0.34692 1.0142 0 -0 0</pose>
        <inertial>
          <pose frame=''>0.000287 -0.000116 -0.053185 0 -0 0</pose>
          <mass>1</mass>
          <inertia>
            <ixx>0.00259003</ixx>
            <ixy>0</ixy>
            <ixz>0</ixz>
            <iyy>0.00262307</iyy>
            <iyz>0</iyz>
            <izz>0.000446024</izz>
          </inertia>
        </inertial>
        <visual name='FrontalLeftElbow_visual'>
          <geometry>
            <mesh>
              <uri>model://teo/meshes/visual/FrontalLeftElbow.dae</uri>
            </mesh>
          </geometry>
          <material>
            <ambient>0.792157 0.819608 0.933333 1</ambient>
            <diffuse>0.792157 0.819608 0.933333 1</diffuse>
            <specular>0.633726 0.655686 0.746667 1</specular>
            <emissive>0 0 0 1</emissive>
          </material>
        </visual>
        <collision name='FrontalLeftElbow_collision'>
          <geometry>
            <mesh>
              <uri>model://teo/meshes/collision/FrontalLeftElbow.stl</uri>
            </mesh>
          </geometry>
          <max_contacts>10</max_contacts>
          <surface>
            <contact>
              <ode/>
            </contact>
            <bounce/>
            <friction>
              <torsional>
                <ode/>
              </torsional>
              <ode/>
            </friction>
          </surface>
        </collision>
        <self_collide>0</self_collide>
        <enable_wind>0</enable_wind>
        <kinematic>0</kinematic>
      </link>
      <joint name='TEO::TEO_leftArm::FrontalLeftElbow' type='revolute'>
        <parent>TEO::TEO_leftArm::AxialLeftShoulder_link</parent>
        <child>TEO::TEO_leftArm::FrontalLeftElbow_link</child>
        <axis>
          <xyz>0 1 0</xyz>
          <limit>
            <lower>-1.76</lower>
            <upper>1.69</upper>
          </limit>
          <dynamics>
            <damping>0.001</damping>
            <friction>0.7</friction>
            <spring_reference>0</spring_reference>
            <spring_stiffness>0</spring_stiffness>
          </dynamics>
          <use_parent_model_frame>0</use_parent_model_frame>
        </axis>
      </joint>
      <link name='TEO::TEO_leftArm::AxialLeftWrist_link'>
        <pose frame=''>0 0.34692 0.8122 0 -0 0</pose>
        <inertial>
          <pose frame=''>-0.001151 0.000603 0.02464 0 -0 0</pose>
          <mass>0.63149</mass>
          <inertia>
            <ixx>0.000701463</ixx>
            <ixy>-1.05e-05</ixy>
            <ixz>-1.09e-05</ixz>
            <iyy>0.000612806</iyy>
            <iyz>1.15e-05</iyz>
            <izz>0.000326949</izz>
          </inertia>
        </inertial>
        <visual name='AxialLeftWrist_visual'>
          <geometry>
            <mesh>
              <uri>model://teo/meshes/visual/AxialLeftWrist.dae</uri>
            </mesh>
          </geometry>
          <material>
            <ambient>0.792157 0.819608 0.933333 1</ambient>
            <diffuse>0.792157 0.819608 0.933333 1</diffuse>
            <specular>0.633726 0.655686 0.746667 1</specular>
            <emissive>0 0 0 1</emissive>
          </material>
        </visual>
        <collision name='AxialLeftWrist_collision'>
          <geometry>
            <mesh>
              <uri>model://teo/meshes/collision/AxialLeftWrist.stl</uri>
            </mesh>
          </geometry>
          <max_contacts>10</max_contacts>
          <surface>
            <contact>
              <ode/>
            </contact>
            <bounce/>
            <friction>
              <torsional>
                <ode/>
              </torsional>
              <ode/>
            </friction>
          </surface>
        </collision>
        <self_collide>0</self_collide>
        <enable_wind>0</enable_wind>
        <kinematic>0</kinematic>
      </link>
      <joint name='TEO::TEO_leftArm::AxialLeftWrist' type='revolute'>
        <parent>TEO::TEO_leftArm::FrontalLeftElbow_link</parent>
        <child>TEO::TEO_leftArm::AxialLeftWrist_link</child>
        <axis>
          <xyz>0 0 1</xyz>
          <limit>
            <lower>-1.77</lower>
            <upper>1.33</upper>
          </limit>
          <dynamics>
            <damping>0.001</damping>
            <friction>0.7</friction>
            <spring_reference>0</spring_reference>
            <spring_stiffness>0</spring_stiffness>
          </dynamics>
          <use_parent_model_frame>0</use_parent_model_frame>
        </axis>
      </joint>
      <link name='TEO::TEO_leftArm::FrontalLeftWrist_link'>
        <pose frame=''>0 0.34692 0.8122 0 -0 0</pose>
        <inertial>
          <pose frame=''>-0.002314 7e-05 -0.108635 0 -0 0</pose>
          <mass>1.17</mass>
          <inertia>
            <ixx>0.00533065</ixx>
            <ixy>1.28e-07</ixy>
            <ixz>0.000100487</ixz>
            <iyy>0.00534528</iyy>
            <iyz>-8.07e-06</iyz>
            <izz>0.000882489</izz>
          </inertia>
        </inertial>
        <visual name='FrontalLeftWrist_visual'>
          <geometry>
            <mesh>
              <uri>model://teo/meshes/visual/FrontalLeftWrist.dae</uri>
            </mesh>
          </geometry>
          <material>
            <ambient>0.792157 0.819608 0.933333 1</ambient>
            <diffuse>0.792157 0.819608 0.933333 1</diffuse>
            <specular>0.633726 0.655686 0.746667 1</specular>
            <emissive>0 0 0 1</emissive>
          </material>
        </visual>
        <collision name='FrontalLeftWrist_collision'>
          <geometry>
            <mesh>
              <uri>model://teo/meshes/collision/FrontalLeftWrist.stl</uri>
            </mesh>
          </geometry>
          <max_contacts>10</max_contacts>
          <surface>
            <contact>
              <ode/>
            </contact>
            <bounce/>
            <friction>
              <torsional>
                <ode/>
              </torsional>
              <ode/>
            </friction>
          </surface>
        </collision>
        <self_collide>0</self_collide>
        <enable_wind>0</enable_wind>
        <kinematic>0</kinematic>
      </link>
      <joint name='TEO::TEO_leftArm::FrontalLeftWrist' type='revolute'>
        <parent>TEO::TEO_leftArm::AxialLeftWrist_link</parent>
        <child>TEO::TEO_leftArm::FrontalLeftWrist_link</child>
        <axis>
          <xyz>0 1 0</xyz>
          <limit>
            <lower>-1.98</lower>
            <upper>1.07</upper>
          </limit>
          <dynamics>
            <damping>0.001</damping>
            <friction>0.7</friction>
            <spring_reference>0</spring_reference>
            <spring_stiffness>0</spring_stiffness>
          </dynamics>
          <use_parent_model_frame>0</use_parent_model_frame>
        </axis>
      </joint>
      <plugin name='controlboard_leftArm' filename='libgazebo_yarp_controlboard.so'>
        <yarpConfigurationFile>model://teo/conf/gazebo_teo_leftArm.ini</yarpConfigurationFile>
      </plugin>
      <link name='TEO::TEO_rightLeg::AxialRightHip_link'>
        <pose frame=''>0 -0.146 0.845 0 -0 0</pose>
        <inertial>
          <pose frame=''>8.9e-05 -0.000389 -0.065985 0 -0 0</pose>
          <mass>0.84945</mass>
          <inertia>
            <ixx>0.0015642</ixx>
            <ixy>0</ixy>
            <ixz>2.5e-06</ixz>
            <iyy>0.00264509</iyy>
            <iyz>0</iyz>
            <izz>0.00170635</izz>
          </inertia>
        </inertial>
        <visual name='AxialRightHip_visual'>
          <geometry>
            <mesh>
              <uri>model://teo/meshes/visual/AxialRightHip.dae</uri>
            </mesh>
          </geometry>
          <material>
            <ambient>0.792157 0.819608 0.933333 1</ambient>
            <diffuse>0.792157 0.819608 0.933333 1</diffuse>
            <specular>0.633726 0.655686 0.746667 1</specular>
            <emissive>0 0 0 1</emissive>
          </material>
        </visual>
        <collision name='AxialRightHip_collision'>
          <geometry>
            <mesh>
              <uri>model://teo/meshes/collision/AxialRightHip.stl</uri>
            </mesh>
          </geometry>
          <max_contacts>10</max_contacts>
          <surface>
            <contact>
              <ode/>
            </contact>
            <bounce/>
            <friction>
              <torsional>
                <ode/>
              </torsional>
              <ode/>
            </friction>
          </surface>
        </collision>
        <self_collide>0</self_collide>
        <enable_wind>0</enable_wind>
        <kinematic>0</kinematic>
      </link>
      <joint name='TEO::TEO_rightLeg::AxialRightHip' type='revolute'>
        <parent>TEO::RootWaist_links</parent>
        <child>TEO::TEO_rightLeg::AxialRightHip_link</child>
        <axis>
          <xyz>0 0 1</xyz>
          <limit>
            <lower>-0.57</lower>
            <upper>0.49</upper>
          </limit>
          <dynamics>
            <damping>0.001</damping>
            <friction>0.7</friction>
            <spring_reference>0</spring_reference>
            <spring_stiffness>0</spring_stiffness>
          </dynamics>
          <use_parent_model_frame>0</use_parent_model_frame>
        </axis>
      </joint>
      <link name='TEO::TEO_rightLeg::SagittalRightHip_link'>
        <pose frame=''>0 -0.146 0.753 0 -0 0</pose>
        <inertial>
          <pose frame=''>-0.000636 0.001058 0.000349 0 -0 0</pose>
          <mass>1.45459</mass>
          <inertia>
            <ixx>0.00154582</ixx>
            <ixy>-2.97e-06</ixy>
            <ixz>-4.07e-09</ixz>
            <iyy>0.00119159</iyy>
            <iyz>9.16e-09</iyz>
            <izz>0.00227048</izz>
          </inertia>
        </inertial>
        <visual name='SagittalRightHip_visual'>
          <geometry>
            <mesh>
              <uri>model://teo/meshes/visual/SagittalRightHip.dae</uri>
            </mesh>
          </geometry>
          <material>
            <ambient>0.792157 0.819608 0.933333 1</ambient>
            <diffuse>0.792157 0.819608 0.933333 1</diffuse>
            <specular>0.633726 0.655686 0.746667 1</specular>
            <emissive>0 0 0 1</emissive>
          </material>
        </visual>
        <collision name='SagittalRightHip_collision'>
          <geometry>
            <mesh>
              <uri>model://teo/meshes/collision/SagittalRightHip.stl</uri>
            </mesh>
          </geometry>
          <max_contacts>10</max_contacts>
          <surface>
            <contact>
              <ode/>
            </contact>
            <bounce/>
            <friction>
              <torsional>
                <ode/>
              </torsional>
              <ode/>
            </friction>
          </surface>
        </collision>
        <self_collide>0</self_collide>
        <enable_wind>0</enable_wind>
        <kinematic>0</kinematic>
      </link>
      <joint name='TEO::TEO_rightLeg::SagittalRightHip' type='revolute'>
        <parent>TEO::TEO_rightLeg::AxialRightHip_link</parent>
        <child>TEO::TEO_rightLeg::SagittalRightHip_link</child>
        <axis>
          <xyz>1 0 0</xyz>
          <limit>
            <lower>-0.25</lower>
            <upper>0.22</upper>
          </limit>
          <dynamics>
            <damping>0.001</damping>
            <friction>0.7</friction>
            <spring_reference>0</spring_reference>
            <spring_stiffness>0</spring_stiffness>
          </dynamics>
          <use_parent_model_frame>0</use_parent_model_frame>
        </axis>
      </joint>
      <link name='TEO::TEO_rightLeg::FrontalRightHip_link'>
        <pose frame=''>0 -0.146 0.753 0 -0 0</pose>
        <inertial>
          <pose frame=''>-0.010862 -6e-06 -0.161205 0 -0 0</pose>
          <mass>1.89152</mass>
          <inertia>
            <ixx>0.0150777</ixx>
            <ixy>0</ixy>
            <ixz>-0.000442074</ixz>
            <iyy>0.015112</iyy>
            <iyz>0</iyz>
            <izz>0.00747346</izz>
          </inertia>
        </inertial>
        <visual name='FrontalRightHip_visual'>
          <geometry>
            <mesh>
              <uri>model://teo/meshes/visual/FrontalRightHip.dae</uri>
            </mesh>
          </geometry>
          <material>
            <ambient>1 1 1 1</ambient>
            <diffuse>0.7 0.7 0.7 1</diffuse>
            <specular>0.2 0.2 0.2 1</specular>
            <emissive>0 0 0 1</emissive>
          </material>
        </visual>
        <collision name='FrontalRightHip_collision'>
          <geometry>
            <mesh>
              <uri>model://teo/meshes/collision/FrontalRightHip.stl</uri>
            </mesh>
          </geometry>
          <max_contacts>10</max_contacts>
          <surface>
            <contact>
              <ode/>
            </contact>
            <bounce/>
            <friction>
              <torsional>
                <ode/>
              </torsional>
              <ode/>
            </friction>
          </surface>
        </collision>
        <self_collide>0</self_collide>
        <enable_wind>0</enable_wind>
        <kinematic>0</kinematic>
      </link>
      <joint name='TEO::TEO_rightLeg::FrontalRightHip' type='revolute'>
        <parent>TEO::TEO_rightLeg::SagittalRightHip_link</parent>
        <child>TEO::TEO_rightLeg::FrontalRightHip_link</child>
        <axis>
          <xyz>0 1 0</xyz>
          <limit>
            <lower>-0.55</lower>
            <upper>0.74</upper>
          </limit>
          <dynamics>
            <damping>0.001</damping>
            <friction>0.7</friction>
            <spring_reference>0</spring_reference>
            <spring_stiffness>0</spring_stiffness>
          </dynamics>
          <use_parent_model_frame>0</use_parent_model_frame>
        </axis>
      </joint>
      <link name='TEO::TEO_rightLeg::FrontalRightKnee_link'>
        <pose frame=''>0 -0.146 0.423 0 -0 0</pose>
        <inertial>
          <pose frame=''>-0.006614 -0.000411 -0.146413 0 -0 0</pose>
          <mass>1.94824</mass>
          <inertia>
            <ixx>0.0218617</ixx>
            <ixy>0</ixy>
            <ixz>3.16e-06</ixz>
            <iyy>0.0214111</iyy>
            <iyz>0</iyz>
            <izz>0.00384364</izz>
          </inertia>
        </inertial>
        <visual name='FrontalRightKnee_visual'>
          <geometry>
            <mesh>
              <uri>model://teo/meshes/visual/FrontalRightKnee.dae</uri>
            </mesh>
          </geometry>
          <material>
            <ambient>1 1 1 1</ambient>
            <diffuse>0.7 0.7 0.7 1</diffuse>
            <specular>0.2 0.2 0.2 1</specular>
            <emissive>0 0 0 1</emissive>
          </material>
        </visual>
        <collision name='FrontalRightKnee_collision'>
          <geometry>
            <mesh>
              <uri>model://teo/meshes/collision/FrontalRightKnee.stl</uri>
            </mesh>
          </geometry>
          <max_contacts>10</max_contacts>
          <surface>
            <contact>
              <ode/>
            </contact>
            <bounce/>
            <friction>
              <torsional>
                <ode/>
              </torsional>
              <ode/>
            </friction>
          </surface>
        </collision>
        <self_collide>0</self_collide>
        <enable_wind>0</enable_wind>
        <kinematic>0</kinematic>
      </link>
      <joint name='TEO::TEO_rightLeg::FrontalRightKnee' type='revolute'>
        <parent>TEO::TEO_rightLeg::FrontalRightHip_link</parent>
        <child>TEO::TEO_rightLeg::FrontalRightKnee_link</child>
        <axis>
          <xyz>0 1 0</xyz>
          <limit>
            <lower>-1.07</lower>
            <upper>1.44</upper>
          </limit>
          <dynamics>
            <damping>0.001</damping>
            <friction>0.7</friction>
            <spring_reference>0</spring_reference>
            <spring_stiffness>0</spring_stiffness>
          </dynamics>
          <use_parent_model_frame>0</use_parent_model_frame>
        </axis>
      </joint>
      <link name='TEO::TEO_rightLeg::FrontalRightAnkle_link'>
        <pose frame=''>0 -0.1285 0.123 0 -0 0</pose>
        <inertial>
          <pose frame=''>0.002577 -0.013536 0.000182 0 -0 0</pose>
          <mass>1.50359</mass>
          <inertia>
            <ixx>0.00139549</ixx>
            <ixy>6.85e-06</ixy>
            <ixz>1e-11</ixz>
            <iyy>0.00158936</iyy>
            <iyz>0</iyz>
            <izz>0.00241866</izz>
          </inertia>
        </inertial>
        <visual name='FrontalRightAnkle_visual'>
          <geometry>
            <mesh>
              <uri>model://teo/meshes/visual/FrontalRightAnkle.dae</uri>
            </mesh>
          </geometry>
          <material>
            <ambient>0.792157 0.819608 0.933333 1</ambient>
            <diffuse>0.792157 0.819608 0.933333 1</diffuse>
            <specular>0.633726 0.655686 0.746667 1</specular>
            <emissive>0 0 0 1</emissive>
          </material>
        </visual>
        <collision name='FrontalRightAnkle_collision'>
          <geometry>
            <mesh>
              <uri>model://teo/meshes/collision/FrontalRightAnkle.stl</uri>
            </mesh>
          </geometry>
          <max_contacts>10</max_contacts>
          <surface>
            <contact>
              <ode/>
            </contact>
            <bounce/>
            <friction>
              <torsional>
                <ode/>
              </torsional>
              <ode/>
            </friction>
          </surface>
        </collision>
        <self_collide>0</self_collide>
        <enable_wind>0</enable_wind>
        <kinematic>0</kinematic>
      </link>
      <joint name='TEO::TEO_rightLeg::FrontalRightAnkle' type='revolute'>
        <parent>TEO::TEO_rightLeg::FrontalRightKnee_link</parent>
        <child>TEO::TEO_rightLeg::FrontalRightAnkle_link</child>
        <axis>
          <xyz>0 1 0</xyz>
          <limit>
            <lower>-0.4</lower>
            <upper>0.44</upper>
          </limit>
          <dynamics>
            <damping>0.001</damping>
            <friction>0.7</friction>
            <spring_reference>0</spring_reference>
            <spring_stiffness>0</spring_stiffness>
          </dynamics>
          <use_parent_model_frame>0</use_parent_model_frame>
        </axis>
      </joint>
      <link name='TEO::TEO_rightLeg::SagittalRightAnkle_link'>
        <pose frame=''>0 -0.1285 0.123 0 -0 0</pose>
        <inertial>
          <pose frame=''>0.01003 0.000936 -0.0669 0 -0 0</pose>
          <mass>3.1334</mass>
          <inertia>
            <ixx>0.00774203</ixx>
            <ixy>0.000455866</ixy>
            <ixz>-0.00185166</ixz>
            <iyy>0.0147813</iyy>
            <iyz>-0.000147513</iyz>
            <izz>0.0133617</izz>
          </inertia>
        </inertial>
        <visual name='FrontalRightAnkle_visual'>
          <geometry>
            <mesh>
              <uri>model://teo/meshes/visual/SagittalRightAnkle.dae</uri>
            </mesh>
          </geometry>
          <material>
            <ambient>0.792157 0.819608 0.933333 1</ambient>
            <diffuse>0.792157 0.819608 0.933333 1</diffuse>
            <specular>0.633726 0.655686 0.746667 1</specular>
            <emissive>0 0 0 1</emissive>
          </material>
        </visual>
        <collision name='SagittalRightAnkle_collision'>
          <geometry>
            <mesh>
              <uri>model://teo/meshes/collision/SagittalRightAnkle.stl</uri>
            </mesh>
          </geometry>
          <max_contacts>4</max_contacts>
          <surface>
            <contact>
              <ode>
                <kp>1.8e+07</kp>
                <kd>100</kd>
                <max_vel>100</max_vel>
                <min_depth>0.0001</min_depth>
              </ode>
            </contact>
            <friction>
              <ode/>
              <torsional>
                <ode/>
              </torsional>
            </friction>
            <bounce/>
          </surface>
        </collision>
        <self_collide>0</self_collide>
        <enable_wind>0</enable_wind>
        <kinematic>0</kinematic>
      </link>
      <joint name='TEO::TEO_rightLeg::SagittalRightAnkle' type='revolute'>
        <parent>TEO::TEO_rightLeg::FrontalRightAnkle_link</parent>
        <child>TEO::TEO_rightLeg::SagittalRightAnkle_link</child>
        <axis>
          <xyz>1 0 0</xyz>
          <limit>
            <lower>-0.35</lower>
            <upper>0.74</upper>
          </limit>
          <dynamics>
            <damping>0.001</damping>
            <friction>0.7</friction>
            <spring_reference>0</spring_reference>
            <spring_stiffness>0</spring_stiffness>
          </dynamics>
          <use_parent_model_frame>0</use_parent_model_frame>
        </axis>
      </joint>
      <plugin name='controlboard_rightLeg' filename='libgazebo_yarp_controlboard.so'>
        <yarpConfigurationFile>model://teo/conf/gazebo_teo_rightLeg.ini</yarpConfigurationFile>
      </plugin>
      <link name='TEO::TEO_leftLeg::AxialLeftHip_link'>
        <pose frame=''>0 0.146 0.845 0 -0 0</pose>
        <inertial>
          <pose frame=''>8.9e-05 -0.000389 -0.065985 0 -0 0</pose>
          <mass>0.84945</mass>
          <inertia>
            <ixx>0.0015642</ixx>
            <ixy>2.5e-06</ixy>
            <ixz>0</ixz>
            <iyy>0.00264509</iyy>
            <iyz>0</iyz>
            <izz>0.00170635</izz>
          </inertia>
        </inertial>
        <visual name='AxialLeftHip_visual'>
          <geometry>
            <mesh>
              <uri>model://teo/meshes/visual/AxialLeftHip.dae</uri>
            </mesh>
          </geometry>
          <material>
            <ambient>0.792157 0.819608 0.933333 1</ambient>
            <diffuse>0.792157 0.819608 0.933333 1</diffuse>
            <specular>0.633726 0.655686 0.746667 1</specular>
            <emissive>0 0 0 1</emissive>
          </material>
        </visual>
        <collision name='AxialLeftHip_collision'>
          <geometry>
            <mesh>
              <uri>model://teo/meshes/collision/AxialLeftHip.stl</uri>
            </mesh>
          </geometry>
          <max_contacts>10</max_contacts>
          <surface>
            <contact>
              <ode/>
            </contact>
            <bounce/>
            <friction>
              <torsional>
                <ode/>
              </torsional>
              <ode/>
            </friction>
          </surface>
        </collision>
        <self_collide>0</self_collide>
        <enable_wind>0</enable_wind>
        <kinematic>0</kinematic>
      </link>
      <joint name='TEO::TEO_leftLeg::AxialLeftHip' type='revolute'>
        <parent>TEO::RootWaist_links</parent>
        <child>TEO::TEO_leftLeg::AxialLeftHip_link</child>
        <axis>
          <xyz>0 0 1</xyz>
          <limit>
            <lower>-0.49</lower>
            <upper>0.57</upper>
          </limit>
          <dynamics>
            <damping>0.001</damping>
            <friction>0.7</friction>
            <spring_reference>0</spring_reference>
            <spring_stiffness>0</spring_stiffness>
          </dynamics>
          <use_parent_model_frame>0</use_parent_model_frame>
        </axis>
      </joint>
      <link name='TEO::TEO_leftLeg::SagittalLeftHip_link'>
        <pose frame=''>0 0.146 0.753 0 -0 0</pose>
        <inertial>
          <pose frame=''>-0.00011 -0.000988 0.000214 0 -0 0</pose>
          <mass>1.45459</mass>
          <inertia>
            <ixx>0.00154582</ixx>
            <ixy>-2.97e-06</ixy>
            <ixz>-4.07e-09</ixz>
            <iyy>0.00119159</iyy>
            <iyz>9.16e-09</iyz>
            <izz>0.00227048</izz>
          </inertia>
        </inertial>
        <visual name='SagittalLeftHip_visual'>
          <geometry>
            <mesh>
              <uri>model://teo/meshes/visual/SagittalLeftHip.dae</uri>
            </mesh>
          </geometry>
          <material>
            <ambient>0.792157 0.819608 0.933333 1</ambient>
            <diffuse>0.792157 0.819608 0.933333 1</diffuse>
            <specular>0.633726 0.655686 0.746667 1</specular>
            <emissive>0 0 0 1</emissive>
          </material>
        </visual>
        <collision name='SagittalLeftHip_collision'>
          <geometry>
            <mesh>
              <uri>model://teo/meshes/collision/SagittalLeftHip.stl</uri>
            </mesh>
          </geometry>
          <max_contacts>10</max_contacts>
          <surface>
            <contact>
              <ode/>
            </contact>
            <bounce/>
            <friction>
              <torsional>
                <ode/>
              </torsional>
              <ode/>
            </friction>
          </surface>
        </collision>
        <self_collide>0</self_collide>
        <enable_wind>0</enable_wind>
        <kinematic>0</kinematic>
      </link>
      <joint name='TEO::TEO_leftLeg::SagittalLeftHip' type='revolute'>
        <parent>TEO::TEO_leftLeg::AxialLeftHip_link</parent>
        <child>TEO::TEO_leftLeg::SagittalLeftHip_link</child>
        <axis>
          <xyz>1 0 0</xyz>
          <limit>
            <lower>-0.22</lower>
            <upper>0.25</upper>
          </limit>
          <dynamics>
            <damping>0.001</damping>
            <friction>0.7</friction>
            <spring_reference>0</spring_reference>
            <spring_stiffness>0</spring_stiffness>
          </dynamics>
          <use_parent_model_frame>0</use_parent_model_frame>
        </axis>
      </joint>
      <link name='TEO::TEO_leftLeg::FrontalLeftHip_link'>
        <pose frame=''>0 0.146 0.753 0 -0 0</pose>
        <inertial>
          <pose frame=''>-0.010862 -6e-06 -0.161205 0 -0 0</pose>
          <mass>1.89152</mass>
          <inertia>
            <ixx>0.0150777</ixx>
            <ixy>0</ixy>
            <ixz>-0.000442074</ixz>
            <iyy>0.015112</iyy>
            <iyz>0</iyz>
            <izz>0.00747346</izz>
          </inertia>
        </inertial>
        <visual name='FrontalLeftHip_visual'>
          <geometry>
            <mesh>
              <uri>model://teo/meshes/visual/FrontalLeftHip.dae</uri>
            </mesh>
          </geometry>
          <material>
            <ambient>1 1 1 1</ambient>
            <diffuse>0.7 0.7 0.7 1</diffuse>
            <specular>0.2 0.2 0.2 1</specular>
            <emissive>0 0 0 1</emissive>
          </material>
        </visual>
        <collision name='FrontalLeftHip_collision'>
          <geometry>
            <mesh>
              <uri>model://teo/meshes/collision/FrontalLeftHip.stl</uri>
            </mesh>
          </geometry>
          <max_contacts>10</max_contacts>
          <surface>
            <contact>
              <ode/>
            </contact>
            <bounce/>
            <friction>
              <torsional>
                <ode/>
              </torsional>
              <ode/>
            </friction>
          </surface>
        </collision>
        <self_collide>0</self_collide>
        <enable_wind>0</enable_wind>
        <kinematic>0</kinematic>
      </link>
      <joint name='TEO::TEO_leftLeg::FrontalLeftHip' type='revolute'>
        <parent>TEO::TEO_leftLeg::SagittalLeftHip_link</parent>
        <child>TEO::TEO_leftLeg::FrontalLeftHip_link</child>
        <axis>
          <xyz>0 1 0</xyz>
          <limit>
            <lower>-0.55</lower>
            <upper>0.74</upper>
          </limit>
          <dynamics>
            <damping>0.001</damping>
            <friction>0.7</friction>
            <spring_reference>0</spring_reference>
            <spring_stiffness>0</spring_stiffness>
          </dynamics>
          <use_parent_model_frame>0</use_parent_model_frame>
        </axis>
      </joint>
      <link name='TEO::TEO_leftLeg::FrontalLeftKnee_link'>
        <pose frame=''>0 0.146 0.423 0 -0 0</pose>
        <inertial>
          <pose frame=''>-0.006614 -0.000411 -0.146413 0 -0 0</pose>
          <mass>1.94824</mass>
          <inertia>
            <ixx>0.0218617</ixx>
            <ixy>0</ixy>
            <ixz>3.16e-06</ixz>
            <iyy>0.0214111</iyy>
            <iyz>0</iyz>
            <izz>0.00384364</izz>
          </inertia>
        </inertial>
        <visual name='FrontalLeftKnee_visual'>
          <geometry>
            <mesh>
              <uri>model://teo/meshes/visual/FrontalLeftKnee.dae</uri>
            </mesh>
          </geometry>
          <material>
            <ambient>1 1 1 1</ambient>
            <diffuse>0.7 0.7 0.7 1</diffuse>
            <specular>0.2 0.2 0.2 1</specular>
            <emissive>0 0 0 1</emissive>
          </material>
        </visual>
        <collision name='FrontalLeftKnee_collision'>
          <geometry>
            <mesh>
              <uri>model://teo/meshes/collision/FrontalLeftKnee.stl</uri>
            </mesh>
          </geometry>
          <max_contacts>10</max_contacts>
          <surface>
            <contact>
              <ode/>
            </contact>
            <bounce/>
            <friction>
              <torsional>
                <ode/>
              </torsional>
              <ode/>
            </friction>
          </surface>
        </collision>
        <self_collide>0</self_collide>
        <enable_wind>0</enable_wind>
        <kinematic>0</kinematic>
      </link>
      <joint name='TEO::TEO_leftLeg::FrontalLeftKnee' type='revolute'>
        <parent>TEO::TEO_leftLeg::FrontalLeftHip_link</parent>
        <child>TEO::TEO_leftLeg::FrontalLeftKnee_link</child>
        <axis>
          <xyz>0 1 0</xyz>
          <limit>
            <lower>-1.07</lower>
            <upper>1.44</upper>
          </limit>
          <dynamics>
            <damping>0.001</damping>
            <friction>0.7</friction>
            <spring_reference>0</spring_reference>
            <spring_stiffness>0</spring_stiffness>
          </dynamics>
          <use_parent_model_frame>0</use_parent_model_frame>
        </axis>
      </joint>
      <link name='TEO::TEO_leftLeg::FrontalLeftAnkle_link'>
        <pose frame=''>0 0.1285 0.123 0 -0 0</pose>
        <inertial>
          <pose frame=''>0.001999 0.013793 3.5e-05 0 -0 0</pose>
          <mass>1.50359</mass>
          <inertia>
            <ixx>0.00139229</ixx>
            <ixy>-1.21e-05</ixy>
            <ixz>1e-11</ixz>
            <iyy>0.00159005</iyy>
            <iyz>1e-11</iyz>
            <izz>0.00241606</izz>
          </inertia>
        </inertial>
        <visual name='FrontalLeftAnkle_visual'>
          <geometry>
            <mesh>
              <uri>model://teo/meshes/visual/FrontalLeftAnkle.dae</uri>
            </mesh>
          </geometry>
          <material>
            <ambient>0.792157 0.819608 0.933333 1</ambient>
            <diffuse>0.792157 0.819608 0.933333 1</diffuse>
            <specular>0.633726 0.655686 0.746667 1</specular>
            <emissive>0 0 0 1</emissive>
          </material>
        </visual>
        <collision name='FrontalLeftAnkle_collision'>
          <geometry>
            <mesh>
              <uri>model://teo/meshes/collision/FrontalLeftAnkle.stl</uri>
            </mesh>
          </geometry>
          <max_contacts>10</max_contacts>
          <surface>
            <contact>
              <ode/>
            </contact>
            <bounce/>
            <friction>
              <torsional>
                <ode/>
              </torsional>
              <ode/>
            </friction>
          </surface>
        </collision>
        <self_collide>0</self_collide>
        <enable_wind>0</enable_wind>
        <kinematic>0</kinematic>
      </link>
      <joint name='TEO::TEO_leftLeg::FrontalLeftAnkle' type='revolute'>
        <parent>TEO::TEO_leftLeg::FrontalLeftKnee_link</parent>
        <child>TEO::TEO_leftLeg::FrontalLeftAnkle_link</child>
        <axis>
          <xyz>0 1 0</xyz>
          <limit>
            <lower>-0.4</lower>
            <upper>0.44</upper>
          </limit>
          <dynamics>
            <damping>0.001</damping>
            <friction>0.7</friction>
            <spring_reference>0</spring_reference>
            <spring_stiffness>0</spring_stiffness>
          </dynamics>
          <use_parent_model_frame>0</use_parent_model_frame>
        </axis>
      </joint>
      <link name='TEO::TEO_leftLeg::SagittalLeftAnkle_link'>
        <pose frame=''>0 0.1285 0.123 0 -0 0</pose>
        <inertial>
          <pose frame=''>0.010136 -0.000799 -0.0669 0 -0 0</pose>
          <mass>3.1334</mass>
          <inertia>
            <ixx>0.00776373</ixx>
            <ixy>-0.000524258</ixy>
            <ixz>-0.00142477</ixz>
            <iyy>0.0145916</iyy>
            <iyz>0.000173925</iyz>
            <izz>0.0131643</izz>
          </inertia>
        </inertial>
        <visual name='SagittalLeftAnkle_visual'>
          <geometry>
            <mesh>
              <uri>model://teo/meshes/visual/SagittalLeftAnkle.dae</uri>
            </mesh>
          </geometry>
          <material>
            <ambient>0.792157 0.819608 0.933333 1</ambient>
            <diffuse>0.792157 0.819608 0.933333 1</diffuse>
            <specular>0.633726 0.655686 0.746667 1</specular>
            <emissive>0 0 0 1</emissive>
          </material>
        </visual>
        <collision name='SagittalLeftAnkle_collision'>
          <geometry>
            <mesh>
              <uri>model://teo/meshes/collision/SagittalLeftAnkle.stl</uri>
            </mesh>
          </geometry>
          <max_contacts>4</max_contacts>
          <surface>
            <contact>
              <ode>
                <kp>1.8e+07</kp>
                <kd>100</kd>
                <max_vel>100</max_vel>
                <min_depth>0.0001</min_depth>
              </ode>
            </contact>
            <friction>
              <ode/>
              <torsional>
                <ode/>
              </torsional>
            </friction>
            <bounce/>
          </surface>
        </collision>
        <self_collide>0</self_collide>
        <enable_wind>0</enable_wind>
        <kinematic>0</kinematic>
      </link>
      <joint name='TEO::TEO_leftLeg::SagittalLeftAnkle' type='revolute'>
        <parent>TEO::TEO_leftLeg::FrontalLeftAnkle_link</parent>
        <child>TEO::TEO_leftLeg::SagittalLeftAnkle_link</child>
        <axis>
          <xyz>1 0 0</xyz>
          <limit>
            <lower>-0.74</lower>
            <upper>0.35</upper>
          </limit>
          <dynamics>
            <damping>0.001</damping>
            <friction>0.7</friction>
            <spring_reference>0</spring_reference>
            <spring_stiffness>0</spring_stiffness>
          </dynamics>
          <use_parent_model_frame>0</use_parent_model_frame>
        </axis>
      </joint>
      <plugin name='controlboard_leftLeg' filename='libgazebo_yarp_controlboard.so'>
        <yarpConfigurationFile>model://teo/conf/gazebo_teo_leftLeg.ini</yarpConfigurationFile>
      </plugin>
      <plugin name='root_state_plugin' filename='libgazebo_yarp_basestate.so'>
        <yarpConfigurationFile>model://teo/conf/teoRoot.ini</yarpConfigurationFile>
      </plugin>
      <joint name='fixed_to_ground' type='fixed'>
        <parent>world</parent>
        <child>TEO::RootWaist_links</child>
      </joint>
      <pose frame=''>0 0 0.05 0 -0 0</pose>
    </model>
    <gravity>0 0 -9.8</gravity>
    <magnetic_field>6e-06 2.3e-05 -4.2e-05</magnetic_field>
    <atmosphere type='adiabatic'/>
    <physics name='default_physics' default='0' type='ode'>
      <max_step_size>0.001</max_step_size>
      <real_time_factor>1</real_time_factor>
      <real_time_update_rate>1000</real_time_update_rate>
    </physics>
    <scene>
      <ambient>0.4 0.4 0.4 1</ambient>
      <background>0.7 0.7 0.7 1</background>
      <shadows>1</shadows>
    </scene>
    <audio>
      <device>default</device>
    </audio>
    <wind/>
    <spherical_coordinates>
      <surface_model>EARTH_WGS84</surface_model>
      <latitude_deg>0</latitude_deg>
      <longitude_deg>0</longitude_deg>
      <elevation>0</elevation>
      <heading_deg>0</heading_deg>
    </spherical_coordinates>
    <model name='Untitled'>
      <link name='link_1'>
        <inertial>
          <mass>1</mass>
          <inertia>
            <ixx>0.166667</ixx>
            <ixy>0</ixy>
            <ixz>0</ixz>
            <iyy>0.166667</iyy>
            <iyz>0</iyz>
            <izz>0.166667</izz>
          </inertia>
          <pose frame=''>0 0 0 0 -0 0</pose>
        </inertial>
        <pose frame=''>0 -0 0 0 -0 0</pose>
        <gravity>0</gravity>
        <self_collide>0</self_collide>
        <kinematic>1</kinematic>
        <enable_wind>0</enable_wind>
        <visual name='visual'>
          <pose frame=''>0 0 0 0 -0 0</pose>
          <geometry>
            <box>
              <size>1 1 0.85</size>
            </box>
          </geometry>
          <material>
            <lighting>1</lighting>
            <script>
              <uri>file://media/materials/scripts/gazebo.material</uri>
              <name>Gazebo/Grey</name>
            </script>
            <shader type='vertex'>
              <normal_map>__default__</normal_map>
            </shader>
            <ambient>0.3 0.3 0.3 1</ambient>
            <diffuse>0.7 0.7 0.7 1</diffuse>
            <specular>0.01 0.01 0.01 1</specular>
            <emissive>0 0 0 1</emissive>
          </material>
          <transparency>0</transparency>
          <cast_shadows>1</cast_shadows>
        </visual>
      </link>
      <static>0</static>
      <allow_auto_disable>1</allow_auto_disable>
      <pose frame=''>0.822659 -0.10108 0 0 -0 0</pose>
    </model>
    <state world_name='default'>
      <sim_time>4821 688000000</sim_time>
      <real_time>4880 8573381</real_time>
      <wall_time>1618587870 435694217</wall_time>
      <iterations>4821688</iterations>
      <model name='TEO_fixed'>
        <pose frame=''>9e-06 1e-05 0.049998 1.2e-05 -1e-05 0</pose>
        <scale>1 1 1</scale>
        <link name='TEO::RootWaist_links'>
          <pose frame=''>0 0 0.894998 1.2e-05 -1e-05 0</pose>
          <velocity>3e-06 -0 3e-06 -0 -0.00024 -5e-06</velocity>
          <acceleration>-0.000246 4.2e-05 0.000599 -0.000358 -0.069096 -0.000464</acceleration>
          <wrench>-0.000616 0.000106 0.001498 0 -0 0</wrench>
        </link>
        <link name='TEO::TEO_head::AxialNeck_link'>
          <pose frame=''>0.005886 -2.2e-05 1.52316 4.3e-05 0.013558 -2.3e-05</pose>
          <velocity>8.3e-05 -1e-06 -1e-06 -2e-06 0.000873 -2e-06</velocity>
          <acceleration>-0.005778 -0.002053 -0.000538 -1.57995 -0.085387 -0.1423</acceleration>
          <wrench>-0.005778 -0.002053 -0.000538 0 -0 0</wrench>
        </link>
        <link name='TEO::TEO_head::FrontalNeck_link'>
          <pose frame=''>0.006325 -2.3e-05 1.55565 4.5e-05 0.012093 -2.3e-05</pose>
          <velocity>6.7e-05 -0 -1e-06 -7e-06 -0.000366 3.5e-05</velocity>
          <acceleration>-0.009284 -0.000401 -0.001114 -0.004379 -0.098267 0.008422</acceleration>
          <wrench>-0.018568 -0.000803 -0.002228 0 -0 0</wrench>
        </link>
        <link name='TEO::TEO_leftArm::AxialLeftShoulder_link'>
          <pose frame=''>-0.001014 0.347326 1.06422 0.001289 0.014172 6.9e-05</pose>
          <velocity>-8.4e-05 1e-06 0 1.5e-05 0.000299 -0.000158</velocity>
          <acceleration>-0.004843 -0.001897 -0.001447 0.000817 -0.001794 -0.030376</acceleration>
          <wrench>-0.004843 -0.001897 -0.001447 0 -0 0</wrench>
        </link>
        <link name='TEO::TEO_leftArm::AxialLeftWrist_link'>
          <pose frame=''>-0.003578 0.347587 0.862237 0.001308 0.012694 0.001467</pose>
          <velocity>-0.000138 5e-06 2e-06 2.6e-05 0.000214 -0.000136</velocity>
          <acceleration>-0.002997 -0.001494 -0.000337 -0.36741 -1.51352 -2.51076</acceleration>
          <wrench>-0.001892 -0.000943 -0.000213 0 -0 0</wrench>
        </link>
        <link name='TEO::TEO_leftArm::FrontalLeftElbow_link'>
          <pose frame=''>-0.001014 0.347326 1.06422 0.001289 0.012696 6.7e-05</pose>
          <velocity>-8.4e-05 1e-06 1e-06 1.9e-05 0.000277 -0.000156</velocity>
          <acceleration>-0.003696 -0.001725 -0.000978 -0.779055 1.47559 -2.42338</acceleration>
          <wrench>-0.003696 -0.001725 -0.000978 0 -0 0</wrench>
        </link>
        <link name='TEO::TEO_leftArm::FrontalLeftShoulder_link'>
          <pose frame=''>0.003765 0.262905 1.39318 6.5e-05 0.014165 0.001382</pose>
          <velocity>-2.7e-05 -5e-06 3e-06 -8e-06 0.000284 -0.001195</velocity>
          <acceleration>0.024734 -0.002865 0.003343 -0.247813 0.441499 -1.73453</acceleration>
          <wrench>0.049467 -0.00573 0.006686 0 -0 0</wrench>
        </link>
        <link name='TEO::TEO_leftArm::FrontalLeftWrist_link'>
          <pose frame=''>-0.003578 0.347587 0.862237 0.001308 0.014005 0.001469</pose>
          <velocity>-0.000139 5e-06 2e-06 2.4e-05 0.000331 -0.000138</velocity>
          <acceleration>-0.000919 -0.001059 -0.000966 0.027128 -0.018341 -0.866203</acceleration>
          <wrench>-0.001076 -0.00124 -0.001131 0 -0 0</wrench>
        </link>
        <link name='TEO::TEO_leftArm::SagittalLeftShoulder_link'>
          <pose frame=''>0.003649 0.346904 1.39319 0.001312 0.01417 0.0014</pose>
          <velocity>3e-05 -2e-06 6e-06 -0.000783 -0.000167 -0.005338</velocity>
          <acceleration>0.063885 0.027136 -0.002087 -3.00197 -0.125774 -0.498517</acceleration>
          <wrench>0.063885 0.027136 -0.002087 0 -0 0</wrench>
        </link>
        <link name='TEO::TEO_leftLeg::AxialLeftHip_link'>
          <pose frame=''>-0 0.146 0.894999 4e-06 -9e-06 0.001399</pose>
          <velocity>-1e-05 0 3e-06 -7e-06 -0.000262 -0.000326</velocity>
          <acceleration>0.004986 -4.7e-05 0.001418 -0.00129 -0.49251 -0.493494</acceleration>
          <wrench>0.004235 -4e-05 0.001204 0 -0 0</wrench>
        </link>
        <link name='TEO::TEO_leftLeg::FrontalLeftAnkle_link'>
          <pose frame=''>-0.001279 0.129954 0.172958 0.00231 0.002241 0.001401</pose>
          <velocity>4e-06 -2e-06 1e-06 -1e-06 0.000119 -1.3e-05</velocity>
          <acceleration>-0.001271 2.7e-05 0.001642 -0.032532 0.176246 0.33996</acceleration>
          <wrench>-0.001912 4e-05 0.002469 0 -0 0</wrench>
        </link>
        <link name='TEO::TEO_leftLeg::FrontalLeftHip_link'>
          <pose frame=''>0 0.146001 0.802996 0.00231 0.001246 0.0014</pose>
          <velocity>9e-06 -0 1e-06 -2e-06 5.4e-05 -1.2e-05</velocity>
          <acceleration>0.002529 -0.000461 0.002098 0.002187 0.026212 0.072979</acceleration>
          <wrench>0.004783 -0.000872 0.003968 0 -0 0</wrench>
        </link>
        <link name='TEO::TEO_leftLeg::FrontalLeftKnee_link'>
          <pose frame=''>-0.000412 0.146762 0.472997 0.002309 0.002968 0.001403</pose>
          <velocity>-1e-05 -1e-06 1e-06 -2e-06 -5.1e-05 -1.3e-05</velocity>
          <acceleration>-0.001031 -0.00027 0.001526 -0.0028 -0.012783 -0.567109</acceleration>
          <wrench>-0.002008 -0.000525 0.002972 0 -0 0</wrench>
        </link>
        <link name='TEO::TEO_leftLeg::SagittalLeftAnkle_link'>
          <pose frame=''>-0.001279 0.129954 0.172958 0.003744 0.002242 0.0014</pose>
          <velocity>4e-06 -2e-06 0 2e-05 -9.3e-05 -1.5e-05</velocity>
          <acceleration>0.000608 0.000246 0.001656 0.036291 0.005291 -0.041386</acceleration>
          <wrench>0.001904 0.000771 0.00519 0 -0 0</wrench>
        </link>
        <link name='TEO::TEO_leftLeg::SagittalLeftHip_link'>
          <pose frame=''>1e-06 0.146001 0.802997 0.002311 -9e-06 0.001398</pose>
          <velocity>1e-05 -0 1e-06 -2e-06 -0.000129 -8e-06</velocity>
          <acceleration>0.008633 -7.1e-05 0.001652 0.163964 -0.401333 -0.530113</acceleration>
          <wrench>0.012557 -0.000103 0.002402 0 -0 0</wrench>
        </link>
        <link name='TEO::TEO_rightArm::AxialRightShoulder_link'>
          <pose frame=''>0.024871 -0.399582 1.06902 -0.160803 -0.06205 0.002342</pose>
          <velocity>-6.3e-05 1e-06 -1e-05 -4e-06 0.000365 4.2e-05</velocity>
          <acceleration>0.014372 0.000287 -0.000312 -0.000854 0.016406 0.003363</acceleration>
          <wrench>0.014372 0.000287 -0.000312 0 -0 0</wrench>
        </link>
        <link name='TEO::TEO_rightArm::AxialRightWrist_link'>
          <pose frame=''>0.039116 -0.431891 0.870124 -0.160796 -0.071133 0.002241</pose>
          <velocity>-0.000136 1e-06 -1.5e-05 0 0.000658 -7e-06</velocity>
          <acceleration>0.018157 0.000429 0.001056 -2.3498 -0.130958 -0.753485</acceleration>
          <wrench>0.011466 0.000271 0.000667 0 -0 0</wrench>
        </link>
        <link name='TEO::TEO_rightArm::FrontalRightElbow_link'>
          <pose frame=''>0.024871 -0.399582 1.06901 -0.160902 -0.070886 0.00378</pose>
          <velocity>-6.1e-05 1e-06 -9e-06 -7e-06 0.000404 7.5e-05</velocity>
          <acceleration>0.01146 0.000165 -0.000633 2.82952 0.930859 -2.57422</acceleration>
          <wrench>0.01146 0.000165 -0.000633 0 -0 0</wrench>
        </link>
        <link name='TEO::TEO_rightArm::FrontalRightShoulder_link'>
          <pose frame=''>0.004489 -0.262935 1.39315 6.6e-05 -0.062207 0.001372</pose>
          <velocity>5.3e-05 -2e-06 -1e-06 1.5e-05 0.000432 0.000193</velocity>
          <acceleration>0.021077 -0.003105 -0.001241 -0.673152 1.3418 -1.74469</acceleration>
          <wrench>0.042153 -0.006209 -0.002483 0 -0 0</wrench>
        </link>
        <link name='TEO::TEO_rightArm::FrontalRightWrist_link'>
          <pose frame=''>0.039116 -0.431891 0.870124 -0.160745 -0.066609 0.001505</pose>
          <velocity>-0.000132 1e-06 -1.4e-05 -3e-06 0.00046 1.8e-05</velocity>
          <acceleration>0.00765 2.8e-05 -5.8e-05 1.55999 -0.638129 -0.670997</acceleration>
          <wrench>0.008951 3.2e-05 -6.8e-05 0 -0 0</wrench>
        </link>
        <link name='TEO::TEO_rightArm::SagittalRightShoulder_link'>
          <pose frame=''>0.004605 -0.346936 1.39314 -0.160726 -0.062202 0.001367</pose>
          <velocity>6.6e-05 1e-06 -2e-06 4.9e-05 0.000513 0.000887</velocity>
          <acceleration>0.025907 -0.004656 -0.000423 3.03362 -1.46327 2.20471</acceleration>
          <wrench>0.025907 -0.004656 -0.000423 0 -0 0</wrench>
        </link>
        <link name='TEO::TEO_rightLeg::AxialRightHip_link'>
          <pose frame=''>0 -0.146 0.895 1e-06 -1e-05 0.001338</pose>
          <velocity>0 0 -0 1e-06 -0.000309 -1e-06</velocity>
          <acceleration>0.010262 -2.5e-05 -0.000697 -0.001267 0.033712 -0.003626</acceleration>
          <wrench>0.008717 -2.1e-05 -0.000592 0 -0 0</wrench>
        </link>
        <link name='TEO::TEO_rightLeg::FrontalRightAnkle_link'>
          <pose frame=''>-0.001275 -0.128837 0.172992 -0.000537 0.00494 0.001335</pose>
          <velocity>2e-06 -0 2e-06 0.000179 3.9e-05 1.4e-05</velocity>
          <acceleration>-0.002848 -0.001838 -0.000161 0.476464 -0.026629 0.914282</acceleration>
          <wrench>-0.004283 -0.002763 -0.000242 0 -0 0</wrench>
        </link>
        <link name='TEO::TEO_rightLeg::FrontalRightHip_link'>
          <pose frame=''>1e-06 -0.145999 0.803 -0.000533 0.001177 0.001337</pose>
          <velocity>8e-06 0 -3e-06 -1e-06 0.000109 -4e-06</velocity>
          <acceleration>-0.025436 -0.000501 -0.001488 -0.003681 0.134377 -0.016743</acceleration>
          <wrench>-0.048113 -0.000947 -0.002814 0 -0 0</wrench>
        </link>
        <link name='TEO::TEO_rightLeg::FrontalRightKnee_link'>
          <pose frame=''>-0.000388 -0.146176 0.473 -0.000533 0.002883 0.001336</pose>
          <velocity>7e-06 -0 0 0 1.8e-05 -2e-06</velocity>
          <acceleration>-0.004877 -0.001237 0.000606 -0.002091 -0.003674 -0.022762</acceleration>
          <wrench>-0.009502 -0.002409 0.001181 0 -0 0</wrench>
        </link>
        <link name='TEO::TEO_rightLeg::SagittalRightAnkle_link'>
          <pose frame=''>-0.001275 -0.128837 0.172992 0.000801 0.00494 0.001335</pose>
          <velocity>2e-06 2e-06 -0 -2.3e-05 2.4e-05 1e-05</velocity>
          <acceleration>-0.005408 0.001277 -0.000619 0.102429 0.086876 -0.178394</acceleration>
          <wrench>-0.016945 0.004001 -0.001941 0 -0 0</wrench>
        </link>
        <link name='TEO::TEO_rightLeg::SagittalRightHip_link'>
          <pose frame=''>1e-06 -0.146 0.803 -0.000533 -2.1e-05 0.001338</pose>
          <velocity>2.5e-05 0 -4e-06 2e-06 0.005088 -3e-06</velocity>
          <acceleration>0.017998 1.5e-05 -0.001178 0.154872 0.22055 0.119098</acceleration>
          <wrench>0.02618 2.2e-05 -0.001714 0 -0 0</wrench>
        </link>
        <link name='TEO::TEO_trunk::AxialWaist_link'>
          <pose frame=''>-2e-06 -2e-06 1.08819 8.8e-05 -7.6e-05 0.001377</pose>
          <velocity>-7.7e-05 -1e-06 8e-06 9e-06 -0.004359 0.000125</velocity>
          <acceleration>0.014269 -0.001622 -0.000481 -0.624563 -0.314657 -0.059416</acceleration>
          <wrench>0.014269 -0.001622 -0.000481 0 -0 0</wrench>
        </link>
        <link name='TEO::TEO_trunk::FrontalWaist_link'>
          <pose frame=''>-1e-06 -0 1.0882 6.7e-05 0.013535 0.001377</pose>
          <velocity>5e-06 -2e-06 -1e-06 4e-06 9.1e-05 0.00013</velocity>
          <acceleration>0.002965 0.000272 0.001318 -0.021974 -0.078652 0.108515</acceleration>
          <wrench>0.04221 0.003872 0.018761 0 -0 0</wrench>
        </link>
      </model>
      <model name='Untitled'>
        <pose frame=''>1 -0.123357 0.45 0 -0 0</pose>
        <scale>1.1946 1 1.08331</scale>
        <link name='link_1'>
          <pose frame=''>1 -0.123357 0.45 0 -0 0</pose>
          <velocity>0 0 0 0 -0 0</velocity>
          <acceleration>0 0 0 0 -0 0</acceleration>
          <wrench>0 0 0 0 -0 0</wrench>
        </link>
      </model>
      <model name='ground_plane'>
        <pose frame=''>0 0 0 0 -0 0</pose>
        <scale>1 1 1</scale>
        <link name='link'>
          <pose frame=''>0 0 0 0 -0 0</pose>
          <velocity>0 0 0 0 -0 0</velocity>
          <acceleration>0 0 0 0 -0 0</acceleration>
          <wrench>0 0 0 0 -0 0</wrench>
        </link>
      </model>
      <light name='sun'>
        <pose frame=''>0 0 10 0 -0 0</pose>
      </light>
    </state>
    <gui fullscreen='0'>
      <camera name='user_camera'>
        <pose frame=''>0.359459 -1.2226 0.839295 0 0.341792 1.38173</pose>
        <view_controller>orbit</view_controller>
        <projection_type>perspective</projection_type>
      </camera>
    </gui>
  </world>
</sdf>
